2025-06-10 10:33:15,643 INFO    MainThread:1419243 [wandb_setup.py:_flush():70] Current SDK version is 0.19.11
2025-06-10 10:33:15,643 INFO    MainThread:1419243 [wandb_setup.py:_flush():70] Configure stats pid to 1419243
2025-06-10 10:33:15,643 INFO    MainThread:1419243 [wandb_setup.py:_flush():70] Loading settings from /home/dyx/.config/wandb/settings
2025-06-10 10:33:15,643 INFO    MainThread:1419243 [wandb_setup.py:_flush():70] Loading settings from /home/dyx/yjl/plato/FedPRC/wandb/settings
2025-06-10 10:33:15,643 INFO    MainThread:1419243 [wandb_setup.py:_flush():70] Loading settings from environment variables
2025-06-10 10:33:15,643 INFO    MainThread:1419243 [wandb_init.py:setup_run_log_directory():724] Logging user logs to /home/dyx/yjl/plato/FedPRC/wandb/run-20250610_103315-bi5d5mas/logs/debug.log
2025-06-10 10:33:15,643 INFO    MainThread:1419243 [wandb_init.py:setup_run_log_directory():725] Logging internal logs to /home/dyx/yjl/plato/FedPRC/wandb/run-20250610_103315-bi5d5mas/logs/debug-internal.log
2025-06-10 10:33:15,643 INFO    MainThread:1419243 [wandb_init.py:init():852] calling init triggers
2025-06-10 10:33:15,643 INFO    MainThread:1419243 [wandb_init.py:init():857] wandb.init called with sweep_config: {}
config: {'_wandb': {}}
2025-06-10 10:33:15,643 INFO    MainThread:1419243 [wandb_init.py:init():893] starting backend
2025-06-10 10:33:15,643 INFO    MainThread:1419243 [wandb_init.py:init():897] sending inform_init request
2025-06-10 10:33:15,668 INFO    MainThread:1419243 [backend.py:_multiprocessing_setup():101] multiprocessing start_methods=fork,spawn,forkserver, using: spawn
2025-06-10 10:33:15,668 INFO    MainThread:1419243 [wandb_init.py:init():907] backend started and connected
2025-06-10 10:33:15,669 INFO    MainThread:1419243 [wandb_init.py:init():1005] updated telemetry
2025-06-10 10:33:15,680 INFO    MainThread:1419243 [wandb_init.py:init():1029] communicating run to backend with 90.0 second timeout
2025-06-10 10:33:46,889 INFO    Thread-3  :1419243 [retry.py:__call__():175] [no run ID] Retry attempt failed:
Traceback (most recent call last):
  File "/home/dyx/yjl/miniconda3/envs/plato/lib/python3.8/site-packages/urllib3/connection.py", line 174, in _new_conn
    conn = connection.create_connection(
  File "/home/dyx/yjl/miniconda3/envs/plato/lib/python3.8/site-packages/urllib3/util/connection.py", line 95, in create_connection
    raise err
  File "/home/dyx/yjl/miniconda3/envs/plato/lib/python3.8/site-packages/urllib3/util/connection.py", line 85, in create_connection
    sock.connect(sa)
socket.timeout: timed out

During handling of the above exception, another exception occurred:

Traceback (most recent call last):
  File "/home/dyx/yjl/miniconda3/envs/plato/lib/python3.8/site-packages/urllib3/connectionpool.py", line 715, in urlopen
    httplib_response = self._make_request(
  File "/home/dyx/yjl/miniconda3/envs/plato/lib/python3.8/site-packages/urllib3/connectionpool.py", line 404, in _make_request
    self._validate_conn(conn)
  File "/home/dyx/yjl/miniconda3/envs/plato/lib/python3.8/site-packages/urllib3/connectionpool.py", line 1060, in _validate_conn
    conn.connect()
  File "/home/dyx/yjl/miniconda3/envs/plato/lib/python3.8/site-packages/urllib3/connection.py", line 363, in connect
    self.sock = conn = self._new_conn()
  File "/home/dyx/yjl/miniconda3/envs/plato/lib/python3.8/site-packages/urllib3/connection.py", line 179, in _new_conn
    raise ConnectTimeoutError(
urllib3.exceptions.ConnectTimeoutError: (<urllib3.connection.HTTPSConnection object at 0x752386956a00>, 'Connection to api.wandb.ai timed out. (connect timeout=20)')

During handling of the above exception, another exception occurred:

Traceback (most recent call last):
  File "/home/dyx/yjl/miniconda3/envs/plato/lib/python3.8/site-packages/requests/adapters.py", line 667, in send
    resp = conn.urlopen(
  File "/home/dyx/yjl/miniconda3/envs/plato/lib/python3.8/site-packages/urllib3/connectionpool.py", line 801, in urlopen
    retries = retries.increment(
  File "/home/dyx/yjl/miniconda3/envs/plato/lib/python3.8/site-packages/urllib3/util/retry.py", line 594, in increment
    raise MaxRetryError(_pool, url, error or ResponseError(cause))
urllib3.exceptions.MaxRetryError: HTTPSConnectionPool(host='api.wandb.ai', port=443): Max retries exceeded with url: /graphql (Caused by ConnectTimeoutError(<urllib3.connection.HTTPSConnection object at 0x752386956a00>, 'Connection to api.wandb.ai timed out. (connect timeout=20)'))

During handling of the above exception, another exception occurred:

Traceback (most recent call last):
  File "/home/dyx/yjl/miniconda3/envs/plato/lib/python3.8/site-packages/wandb/sdk/lib/retry.py", line 134, in __call__
    result = self._call_fn(*args, **kwargs)
  File "/home/dyx/yjl/miniconda3/envs/plato/lib/python3.8/site-packages/wandb/sdk/internal/internal_api.py", line 398, in execute
    return self.client.execute(*args, **kwargs)  # type: ignore
  File "/home/dyx/yjl/miniconda3/envs/plato/lib/python3.8/site-packages/wandb/vendor/gql-0.2.0/wandb_gql/client.py", line 52, in execute
    result = self._get_result(document, *args, **kwargs)
  File "/home/dyx/yjl/miniconda3/envs/plato/lib/python3.8/site-packages/wandb/vendor/gql-0.2.0/wandb_gql/client.py", line 60, in _get_result
    return self.transport.execute(document, *args, **kwargs)
  File "/home/dyx/yjl/miniconda3/envs/plato/lib/python3.8/site-packages/wandb/sdk/lib/gql_request.py", line 58, in execute
    request = self.session.post(self.url, **post_args)
  File "/home/dyx/yjl/miniconda3/envs/plato/lib/python3.8/site-packages/requests/sessions.py", line 637, in post
    return self.request("POST", url, data=data, json=json, **kwargs)
  File "/home/dyx/yjl/miniconda3/envs/plato/lib/python3.8/site-packages/requests/sessions.py", line 589, in request
    resp = self.send(prep, **send_kwargs)
  File "/home/dyx/yjl/miniconda3/envs/plato/lib/python3.8/site-packages/requests/sessions.py", line 703, in send
    r = adapter.send(request, **kwargs)
  File "/home/dyx/yjl/miniconda3/envs/plato/lib/python3.8/site-packages/requests/adapters.py", line 688, in send
    raise ConnectTimeout(e, request=request)
requests.exceptions.ConnectTimeout: HTTPSConnectionPool(host='api.wandb.ai', port=443): Max retries exceeded with url: /graphql (Caused by ConnectTimeoutError(<urllib3.connection.HTTPSConnection object at 0x752386956a00>, 'Connection to api.wandb.ai timed out. (connect timeout=20)'))
2025-06-10 10:33:50,019 WARNING MainThread:1419243 [wandb_init.py:init():1681] [no run ID] interrupted
Traceback (most recent call last):
  File "/home/dyx/yjl/miniconda3/envs/plato/lib/python3.8/site-packages/wandb/sdk/wandb_init.py", line 1677, in init
    return wi.init(run_settings, run_config, run_printer)
  File "/home/dyx/yjl/miniconda3/envs/plato/lib/python3.8/site-packages/wandb/sdk/wandb_init.py", line 1055, in init
    result = wait_with_progress(
  File "/home/dyx/yjl/miniconda3/envs/plato/lib/python3.8/site-packages/wandb/sdk/mailbox/wait_with_progress.py", line 24, in wait_with_progress
    return wait_all_with_progress(
  File "/home/dyx/yjl/miniconda3/envs/plato/lib/python3.8/site-packages/wandb/sdk/mailbox/wait_with_progress.py", line 87, in wait_all_with_progress
    return asyncio_compat.run(progress_loop_with_timeout)
  File "/home/dyx/yjl/miniconda3/envs/plato/lib/python3.8/site-packages/wandb/sdk/lib/asyncio_compat.py", line 30, in run
    return future.result()
  File "/home/dyx/yjl/miniconda3/envs/plato/lib/python3.8/concurrent/futures/_base.py", line 439, in result
    self._condition.wait(timeout)
  File "/home/dyx/yjl/miniconda3/envs/plato/lib/python3.8/threading.py", line 302, in wait
    waiter.acquire()
KeyboardInterrupt
